Workbook

Sheet GVA Eurostat
A1: Data extracted on 06/11/2025 13:39:26 from [ESTAT]
A2: Dataset: | B2: Gross domestic product (GDP) and main components (output, expenditure and income) [namq_10_gdp__custom_18779096]
A3: Last updated: | B3: 31/10/2025 23:00
A5: Time frequency | C5: Quarterly
A6: Unit of measure | C6: Chain linked volumes (2020), million units of national currency
A7: Seasonal adjustment | C7: Unadjusted data (i.e. neither seasonally adjusted nor calendar adjusted data)
A8: National accounts indicator (ESA 2010) | C8: Value added, gross
A10: TIME | B10: 1975-Q1 | D10: 1975-Q2 | F10: 1975-Q3 | H10: 1975-Q4 | J10: 1976-Q1 | L10: 1976-Q2 | N10: 1976-Q3 | P10: 1976-Q4 | R10: 1977-Q1 | T10: 1977-Q2 | V10: 1977-Q3 | X10: 1977-Q4 | Z10: 1978-Q1 | AB10: 1978-Q2 | AD10: 1978-Q3 | AF10: 1978-Q4 | AH10: 1979-Q1 | AJ10: 1979-Q2 | AL10: 1979-Q3 | AN10: 1979-Q4 | AP10: 1980-Q1 | AR10: 1980-Q2 | AT10: 1980-Q3 | AV10: 1980-Q4 | AX10: 1981-Q1 | AZ10: 1981-Q2 | BB10: 1981-Q3 | BD10: 1981-Q4 | BF10: 1982-Q1 | BH10: 1982-Q2 | BJ10: 1982-Q3 | BL10: 1982-Q4 | BN10: 1983-Q1 | BP10: 1983-Q2 | BR10: 1983-Q3 | BT10: 1983-Q4 | BV10: 1984-Q1 | BX10: 1984-Q2 | BZ10: 1984-Q3 | CB10: 1984-Q4 | CD10: 1985-Q1 | CF10: 1985-Q2 | CH10: 1985-Q3 | CJ10: 1985-Q4 | CL10: 1986-Q1 | CN10: 1986-Q2 | CP10: 1986-Q3 | CR10: 1986-Q4 | CT10: 1987-Q1 | CV10: 1987-Q2 | CX10: 1987-Q3 | CZ10: 1987-Q4 | DB10: 1988-Q1 | DD10: 1988-Q2 | DF10: 1988-Q3 | DH10: 1988-Q4 | DJ10: 1989-Q1 | DL10: 1989-Q2 | DN10: 1989-Q3 | DP10: 1989-Q4 | DR10: 1990-Q1 | DT10: 1990-Q2 | DV10: 1990-Q3 | DX10: 1990-Q4 | DZ10: 1991-Q1 | EB10: 1991-Q2 | ED10: 1991-Q3 | EF10: 1991-Q4 | EH10: 1992-Q1 | EJ10: 1992-Q2 | EL10: 1992-Q3 | EN10: 1992-Q4 | EP10: 1993-Q1 | ER10: 1993-Q2 | ET10: 1993-Q3 | EV10: 1993-Q4 | EX10: 1994-Q1 | EZ10: 1994-Q2 | FB10: 1994-Q3 | FD10: 1994-Q4 | FF10: 1995-Q1 | FH10: 1995-Q2 | FJ10: 1995-Q3 | FL10: 1995-Q4 | FN10: 1996-Q1 | FP10: 1996-Q2 | FR10: 1996-Q3 | FT10: 1996-Q4 | FV10: 1997-Q1 | FX10: 1997-Q2 | FZ10: 1997-Q3 | GB10: 1997-Q4 | GD10: 1998-Q1 | GF10: 1998-Q2 | GH10: 1998-Q3 | GJ10: 1998-Q4 | GL10: 1999-Q1 | GN10: 1999-Q2 | GP10: 1999-Q3 | GR10: 1999-Q4 | GT10: 2000-Q1 | GV10: 2000-Q2 | GX10: 2000-Q3 | GZ10: 2000-Q4 | HB10: 2001-Q1 | HD10: 2001-Q2 | HF10: 2001-Q3 | HH10: 2001-Q4 | HJ10: 2002-Q1 | HL10: 2002-Q2 | HN10: 2002-Q3 | HP10: 2002-Q4 | HR10: 2003-Q1 | HT10: 2003-Q2 | HV10: 2003-Q3 | HX10: 2003-Q4 | HZ10: 2004-Q1 | IB10: 2004-Q2 | ID10: 2004-Q3 | IF10: 2004-Q4 | IH10: 2005-Q1 | IJ10: 2005-Q2 | IL10: 2005-Q3 | IN10: 2005-Q4 | IP10: 2006-Q1 | IR10: 2006-Q2 | IT10: 2006-Q3 | IV10: 2006-Q4 | IX10: 2007-Q1 | IZ10: 2007-Q2 | JB10: 2007-Q3 | JD10: 2007-Q4 | JF10: 2008-Q1 | JH10: 2008-Q2 | JJ10: 2008-Q3 | JL10: 2008-Q4 | JN10: 2009-Q1 | JP10: 2009-Q2 | JR10: 2009-Q3 | JT10: 2009-Q4 | JV10: 2010-Q1 | JX10: 2010-Q2 | JZ10: 2010-Q3 | KB10: 2010-Q4 | KD10: 2011-Q1 | KF10: 2011-Q2 | KH10: 2011-Q3 | KJ10: 2011-Q4 | KL10: 2012-Q1 | KN10: 2012-Q2 | KP10: 2012-Q3 | KR10: 2012-Q4 | KT10: 2013-Q1 | KV10: 2013-Q2 | KX10: 2013-Q3 | KZ10: 2013-Q4 | LB10: 2014-Q1 | LD10: 2014-Q2 | LF10: 2014-Q3 | LH10: 2014-Q4 | LJ10: 2015-Q1 | LL10: 2015-Q2 | LN10: 2015-Q3 | LP10: 2015-Q4 | LR10: 2016-Q1 | LT10: 2016-Q2 | LV10: 2016-Q3 | LX10: 2016-Q4 | LZ10: 2017-Q1 | MB10: 2017-Q2 | MD10: 2017-Q3 | MF10: 2017-Q4 | MH10: 2018-Q1 | MJ10: 2018-Q2 | ML10: 2018-Q3 | MN10: 2018-Q4 | MP10: 2019-Q1 | MR10: 2019-Q2 | MT10: 2019-Q3 | MV10: 2019-Q4 | MX10: 2020-Q1 | MZ10: 2020-Q2 | NB10: 2020-Q3 | ND10: 2020-Q4 | NF10: 2021-Q1 | NH10: 2021-Q2 | NJ10: 2021-Q3 | NL10: 2021-Q4 | NN10: 2022-Q1 | NP10: 2022-Q2 | NR10: 2022-Q3 | NT10: 2022-Q4 | NV10: 2023-Q1 | NX10: 2023-Q2 | NZ10: 2023-Q3 | OB10: 2023-Q4 | OD10: 2024-Q1 | OF10: 2024-Q2 | OH10: 2024-Q3 | OJ10: 2024-Q4 | OL10: 2025-Q1 | ON10: 2025-Q2 | OP10: 2025-Q3
A11: GEO (Labels)
A12: Belgium | B12: : | D12: : | F12: : | H12: : | J12: : | L12: : | N12: : | P12: : | R12: : | T12: : | V12: : | X12: : | Z12: : | AB12: : | AD12: : | AF12: : | AH12: : | AJ12: : | AL12: : | AN12: : | AP12: : | AR12: : | AT12: : | AV12: : | AX12: : | AZ12: : | BB12: : | BD12: : | BF12: : | BH12: : | BJ12: : | BL12: : | BN12: : | BP12: : | BR12: : | BT12: : | BV12: : | BX12: : | BZ12: : | CB12: : | CD12: : | CF12: : | CH12: : | CJ12: : | CL12: : | CN12: : | CP12: : | CR12: : | CT12: : | CV12: : | CX12: : | CZ12: : | DB12: : | DD12: : | DF12: : | DH12: : | DJ12: : | DL12: : | DN12: : | DP12: : | DR12: : | DT12: : | DV12: : | DX12: : | DZ12: : | EB12: : | ED12: : | EF12: : | EH12: : | EJ12: : | EL12: : | EN12: : | EP12: : | ER12: : | ET12: : | EV12: : | EX12: : | EZ12: : | FB12: : | FD12: : | FF12: 68971.2 | FH12: 71483.1 | FJ12: 69051.6 | FL12: 73071.7 | FN12: 69675.5 | FP12: 72153 | FR12: 69560.6 | FT12: 73777.8 | FV12: 71823.1 | FX12: 74803.5 | FZ12: 72389.6 | GB12: 76550.6 | GD12: 74121.5 | GF12: 76163.4 | GH12: 73432.5 | GJ12: 77368.9 | GL12: 75341.3 | GN12: 78225.2 | GP12: 76265.3 | GR12: 81270.4 | GT12: 78583.2 | GV12: 81311.6 | GX12: 78513.9 | GZ12: 83850 | HB12: 80449.3 | HD12: 82918.2 | HF12: 79565.1 | HH12: 84225.3 | HJ12: 80916 | HL12: 84191.3 | HN12: 81065.2 | HP12: 86327.8 | HR12: 82129.4 | HT12: 84845.9 | HV12: 81836 | HX12: 87393.3 | HZ12: 84258.4 | IB12: 87641.1 | ID12: 84625.1 | IF12: 90344 | IH12: 86414.9 | IJ12: 89912.8 | IL12: 86491.5 | IN12: 92533.7 | IP12: 88623.4 | IR12: 91831.4 | IT12: 88517 | IV12: 95088 | IX12: 91865.2 | IZ12: 95385.5 | JB12: 92041.6 | JD12: 98344.1 | JF12: 93920.7 | JH12: 97402.4 | JJ12: 92681.2 | JL12: 96607.9 | JN12: 89876.9 | JO12: b | JP12: 93818.6 | JR12: 89817.5 | JT12: 100074.4 | JV12: 92244.6 | JX12: 96961.6 | JZ12: 92082.6 | KB12: 102503.5 | KD12: 94877.4 | KF12: 99321.7 | KH12: 94120.4 | KJ12: 104123.4 | KL12: 95469.5 | KN12: 99571.9 | KP12: 94287.1 | KR12: 103911.6 | KT12: 94876.3 | KV12: 99927.4 | KX12: 94603.8 | KZ12: 104744.4 | LB12: 96863.6 | LD12: 101691.8 | LF12: 96425.3 | LH12: 106613 | LJ12: 98761.8 | LL12: 103783.4 | LN12: 97650.8 | LP12: 107604.3 | LR12: 99695.7 | LT12: 104695.2 | LV12: 98372.7 | LX12: 108580.7 | LZ12: 101375.8 | MB12: 106065.9 | MD12: 99324.8 | MF12: 110446.7 | MH12: 102858.8 | MJ12: 107964.1 | ML12: 101457.1 | MN12: 112951.9 | MP12: 105452.9 | MR12: 110792.9 | MT12: 104472.7 | MV12: 115618.5 | MX12: 105521 | MZ12: 98401.4 | NB12: 101712.8 | ND12: 112359.7 | NF12: 105829.2 | NH12: 111783.4 | NJ12: 105732.1 | NL12: 118448.5 | NN12: 110843.3 | NP12: 117350.8 | NR12: 110150 | NT12: 122338 | NV12: 114004.1 | NX12: 119521.8 | NZ12: 111748.3 | OB12: 123634.4 | OD12: 115399.9 | OE12: p | OF12: 120712.1 | OG12: p | OH12: 112759.2 | OI12: p | OJ12: 124547.1 | OK12: p | OL12: 116249.5 | OM12: p | ON12: 121829.1 | OO12: p | OP12: :
A13: Bulgaria | B13: : | D13: : | F13: : | H13: : | J13: : | L13: : | N13: : | P13: : | R13: : | T13: : | V13: : | X13: : | Z13: : | AB13: : | AD13: : | AF13: : | AH13: : | AJ13: : | AL13: : | AN13: : | AP13: : | AR13: : | AT13: : | AV13: : | AX13: : | AZ13: : | BB13: : | BD13: : | BF13: : | BH13: : | BJ13: : | BL13: : | BN13: : | BP13: : | BR13: : | BT13: : | BV13: : | BX13: : | BZ13: : | CB13: : | CD13: : | CF13: : | CH13: : | CJ13: : | CL13: : | CN13: : | CP13: : | CR13: : | CT13: : | CV13: : | CX13: : | CZ13: : | DB13: : | DD13: : | DF13: : | DH13: : | DJ13: : | DL13: : | DN13: : | DP13: : | DR13: : | DT13: : | DV13: : | DX13: : | DZ13: : | EB13: : | ED13: : | EF13: : | EH13: : | EJ13: : | EL13: : | EN13: : | EP13: : | ER13: : | ET13: : | EV13: : | EX13: : | EZ13: : | FB13: : | FD13: : | FF13: : | FH13: : | FJ13: : | FL13: : | FN13: 15405.7 | FP13: 16425.8 | FR13: 19538.4 | FT13: 19038.7 | FV13: 13106.8 | FX13: 13692.2 | FZ13: 16881.7 | GB13: 16078.3 | GD13: 13798.2 | GF13: 13427 | GH13: 17281.8 | GJ13: 16367.4 | GL13: 12247.1 | GN13: 12321.5 | GP13: 15550.2 | GR13: 15323.6 | GT13: 12280.2 | GV13: 13235.8 | GX13: 16008.8 | GZ13: 16106.9 | HB13: 12760.7 | HD13: 13694 | HF13: 16665.8 | HH13: 16858.2 | HJ13: 13574.6 | HL13: 14806 | HN13: 18123.8 | HP13: 18032.2 | HR13: 14175 | HT13: 15414.6 | HV13: 18622.4 | HX13: 19006.2 | HZ13: 14683.8 | IB13: 16173.5 | ID13: 19803.2 | IF13: 19836.2 | IH13: 15829.8 | IJ13: 17398.6 | IL13: 20708.1 | IN13: 21111 | IP13: 16858.2 | IR13: 18564.6 | IT13: 22108.2 | IV13: 22878 | IX13: 18005.6 | IZ13: 20263.9 | JB13: 23039.8 | JD13: 24365.3 | JF13: 19477.9 | JH13: 21641.5 | JJ13: 24814.2 | JL13: 25011.2 | JN13: 19458.6 | JP13: 21849 | JR13: 24683 | JT13: 24173.3 | JV13: 19165.6 | JX13: 22480.6 | JZ13: 24839.2 | KB13: 25328.4 | KD13: 19281.3 | KF13: 23574.9 | KH13: 25443.9 | KJ13: 25258.8 | KL13: 19364.2 | KN13: 23352.9 | KP13: 25548.7 | KR13: 25529.8 | KT13: 18747.9 | KV13: 22618.1 | KX13: 25271.6 | KZ13: 25612.3 | LB13: 18757.3 | LD13: 22776.2 | LF13: 25288.5 | LH13: 26314.8 | LJ13: 19394.1 | LL13: 23435.2 | LN13: 26377.7 | LP13: 26670.9 | LR13: 19925.5 | LT13: 24004.1 | LV13: 26933.9 | LX13: 27485.1 | LZ13: 20794.7 | MB13: 24793 | MD13: 27677.5 | MF13: 28310.3 | MH13: 21445 | MJ13: 25708.1 | ML13: 28404.6 | MN13: 29133.2 | MP13: 22189.3 | MR13: 26545.2 | MT13: 29429.8 | MV13: 30128.5 | MX13: 22159 | MZ13: 24732.1 | NB13: 28965.8 | ND13: 29147.7 | NF13: 22896.5 | NH13: 26154.7 | NJ13: 31673 | NL13: 32881.3 | NN13: 24317.2 | NP13: 27815.5 | NR13: 33317.1 | NT13: 34420.7 | NV13: 24752.7 | NX13: 28164.5 | NZ13: 33455.8 | OB13: 34735.5 | OD13: 25134.7 | OF13: 28980.3 | OH13: 34415.4 | OJ13: 35954.4 | OL13: 25735.4 | OM13: p | ON13: 29787.8 | OO13: p | OP13: :
A14: Czechia | B14: : | D14: : | F14: : | H14: : | J14: : | L14: : | N14: : | P14: : | R14: : | T14: : | V14: : | X14: : | Z14: : | AB14: : | AD14: : | AF14: : | AH14: : | AJ14: : | AL14: : | AN14: : | AP14: : | AR14: : | AT14: : | AV14: : | AX14: : | AZ14: : | BB14: : | BD14: : | BF14: : | BH14: : | BJ14: : | BL14: : | BN14: : | BP14: : | BR14: : | BT14: : | BV14: : | BX14: : | BZ14: : | CB14: : | CD14: : | CF14: : | CH14: : | CJ14: : | CL14: : | CN14: : | CP14: : | CR14: : | CT14: : | CV14: : | CX14: : | CZ14: : | DB14: : | DD14: : | DF14: : | DH14: : | DJ14: : | DL14: : | DN14: : | DP14: : | DR14: : | DT14: : | DV14: : | DX14: : | DZ14: : | EB14: : | ED14: : | EF14: : | EH14: : | EJ14: : | EL14: : | EN14: : | EP14: : | ER14: : | ET14: : | EV14: : | EX14: : | EZ14: : | FB14: : | FD14: : | FF14: 711003 | FH14: 759153 | FJ14: 779096 | FL14: 787036 | FN14: 737903 | FP14: 795808 | FR14: 809290 | FT14: 808989 | FV14: 736425 | FX14: 790297 | FZ14: 795117 | GB14: 788894 | GD14: 726666 | GF14: 782307 | GH14: 794015 | GJ14: 796222 | GL14: 730558 | GN14: 789347 | GP14: 803074 | GR14: 820311 | GT14: 766717 | GV14: 821826 | GX14: 840091 | GZ14: 849259 | HB14: 794732 | HD14: 846621 | HF14: 857673 | HH14: 875173 | HJ14: 805080 | HL14: 862848 | HN14: 881225 | HP14: 891109 | HR14: 823103 | HT14: 883563 | HV14: 907793 | HX14: 917624 | HZ14: 858375 | IB14: 925850 | ID14: 941295 | IF14: 975008 | IH14: 904709 | IJ14: 989021 | IL14: 1003495 | IN14: 1044962 | IP14: 975717 | IR14: 1058804 | IT14: 1074269 | IV14: 1114063 | IX14: 1035209 | IZ14: 1110642 | JB14: 1124193 | JD14: 1172312 | JF14: 1085731 | JH14: 1162909 | JJ14: 1180360 | JL14: 1168497 | JN14: 1029469 | JP14: 1090629 | JR14: 1106311 | JT14: 1121096 | JV14: 1039846 | JX14: 1132682 | JZ14: 1146330 | KB14: 1172652 | KD14: 1074922 | KF14: 1160454 | KH14: 1159820 | KJ14: 1175777 | KL14: 1087172 | KN14: 1145527 | KP14: 1140031 | KR14: 1160669 | KT14: 1069666 | KV14: 1144863 | KX14: 1152594 | KZ14: 1165748 | LB14: 1091663 | LD14: 1174384 | LF14: 1193148 | LH14: 1202134 | LJ14: 1136654 | LL14: 1225790 | LN14: 1245062 | LP14: 1256588 | LR14: 1168440 | LT14: 1265513 | LV14: 1266132 | LX14: 1287860 | LZ14: 1223434 | MB14: 1327903 | MD14: 1338890 | MF14: 1357412 | MH14: 1270362 | MJ14: 1363628 | ML14: 1369912 | MN14: 1399703 | MP14: 1315048 | MR14: 1410533 | MT14: 1430885 | MV14: 1441645 | MX14: 1304336 | MZ14: 1261910 | NB14: 1366778 | ND14: 1382342 | NF14: 1284529 | NH14: 1394162 | NJ14: 1412227 | NL14: 1433306 | NN14: 1343910 | NP14: 1445755 | NR14: 1441268 | NT14: 1453691 | NV14: 1368749 | NX14: 1447369 | NZ14: 1442507 | OB14: 1457886 | OD14: 1353709 | OF14: 1450642 | OH14: 1468106 | OJ14: 1477936 | OL14: 1389845 | ON14: 1487054 | OP14: :
A15: Denmark | B15: : | D15: : | F15: : | H15: : | J15: : | L15: : | N15: : | P15: : | R15: : | T15: : | V15: : | X15: : | Z15: : | AB15: : | AD15: : | AF15: : | AH15: : | AJ15: : | AL15: : | AN15: : | AP15: : | AR15: : | AT15: : | AV15: : | AX15: : | AZ15: : | BB15: : | BD15: : | BF15: : | BH15: : | BJ15: : | BL15: : | BN15: : | BP15: : | BR15: : | BT15: : | BV15: : | BX15: : | BZ15: : | CB15: : | CD15: : | CF15: : | CH15: : | CJ15: : | CL15: : | CN15: : | CP15: : | CR15: : | CT15: : | CV15: : | CX15: : | CZ15: : | DB15: : | DD15: : | DF15: : | DH15: : | DJ15: : | DL15: : | DN15: : | DP15: : | DR15: : | DT15: : | DV15: : | DX15: : | DZ15: : | EB15: : | ED15: : | EF15: : | EH15: : | EJ15: : | EL15: : | EN15: : | EP15: : | ER15: : | ET15: : | EV15: : | EX15: : | EZ15: : | FB15: : | FD15: : | FF15: 353844.7 | FH15: 358393.9 | FJ15: 346778.9 | FL15: 366831.3 | FN15: 353866.5 | FP15: 370397.6 | FR15: 359740.4 | FT15: 377802.5 | FV15: 364651.3 | FX15: 384399.1 | FZ15: 370761.3 | GB15: 387621.3 | GD15: 377522.2 | GF15: 380656.4 | GH15: 379471.5 | GJ15: 399428.4 | GL15: 383320.8 | GN15: 397641.7 | GP15: 391278.3 | GR15: 415895.4 | GT15: 399961.2 | GV15: 414226.1 | GX15: 410612.4 | GZ15: 436830.7 | HB15: 407136.4 | HD15: 418022.4 | HF15: 415993.7 | HH15: 436875.8 | HJ15: 405722.2 | HL15: 425707.3 | HN15: 417811.4 | HP15: 433948.9 | HR15: 412452.5 | HT15: 421601.4 | HV15: 414946.3 | HX15: 441761.9 | HZ15: 417423.7 | IB15: 434313.9 | ID15: 426221.2 | IF15: 448105.1 | IH15: 416862.4 | IJ15: 447699 | IL15: 435281.8 | IN15: 454716.2 | IP15: 435036.5 | IR15: 463605.4 | IT15: 453107.9 | IV15: 468523.4 | IX15: 444187.2 | IZ15: 453461.8 | JB15: 456135.2 | JD15: 477498.5 | JF15: 448805.8 | JH15: 465926.2 | JJ15: 456685.1 | JL15: 463137.4 | JN15: 432527.1 | JP15: 436456 | JR15: 434109.3 | JT15: 447925.2 | JV15: 427705.9 | JX15: 446076.9 | JZ15: 446793.3 | KB15: 456977 | KD15: 440127.5 | KF15: 455865.8 | KH15: 445965.8 | KJ15: 461453.7 | KL15: 440824.8 | KN15: 452688.6 | KP15: 449236.5 | KR15: 460626.5 | KT15: 441457.3 | KV15: 461768.7 | KX15: 457375.6 | KZ15: 468747.4 | LB15: 449120.7 | LD15: 461949.2 | LF15: 463707.6 | LH15: 475270.7 | LJ15: 456699.2 | LL15: 476869.6 | LN15: 468924.1 | LP15: 483705.7 | LR15: 463536 | LT15: 491331.3 | LV15: 485217.8 | LX15: 502332.4 | LZ15: 483522 | MB15: 507867.8 | MD15: 497423.1 | MF15: 515995.4 | MH15: 491097.2 | MJ15: 515979.5 | ML15: 506018.9 | MN15: 523011.2 | MP15: 497715.4 | MR15: 524453.9 | MT15: 515915.3 | MV15: 532271 | MX15: 503009.8 | MZ15: 486342.1 | NB15: 504245.2 | ND15: 527723.3 | NF15: 500012 | NH15: 537549 | NJ15: 536538 | NL15: 584536.8 | NN15: 519952.8 | NP15: 549697.1 | NR15: 547010 | NT15: 571560.6 | NV15: 538550.9 | NX15: 552622.8 | NZ15: 542068.1 | OB15: 586557.2 | OD15: 546013.3 | OF15: 579431.4 | OH15: 567261.9 | OJ15: 611941.2 | OL15: 563190.3 | ON15: 586182 | OP15: :
A16: Germany | B16: : | D16: : | F16: : | H16: : | J16: : | L16: : | N16: : | P16: : | R16: : | T16: : | V16: : | X16: : | Z16: : | AB16: : | AD16: : | AF16: : | AH16: : | AJ16: : | AL16: : | AN16: : | AP16: : | AR16: : | AT16: : | AV16: : | AX16: : | AZ16: : | BB16: : | BD16: : | BF16: : | BH16: : | BJ16: : | BL16: : | BN16: : | BP16: : | BR16: : | BT16: : | BV16: : | BX16: : | BZ16: : | CB16: : | CD16: : | CF16: : | CH16: : | CJ16: : | CL16: : | CN16: : | CP16: : | CR16: : | CT16: : | CV16: : | CX16: : | CZ16: : | DB16: : | DD16: : | DF16: : | DH16: : | DJ16: : | DL16: : | DN16: : | DP16: : | DR16: : | DT16: : | DV16: : | DX16: : | DZ16: 530814.1 | EB16: 536936.8 | ED16: 543524.5 | EF16: 554684.9 | EH16: 546004.6 | EJ16: 545772.1 | EL16: 556157.4 | EN16: 562125.1 | EP16: 532441.7 | ER16: 540501.9 | ET16: 551429.8 | EV16: 559335 | EX16: 540656.9 | EZ16: 551894.8 | FB16: 563985.2 | FD16: 576075.5 | FF16: 555924.9 | FH16: 561970.1 | FJ16: 572510.4 | FL16: 582663.2 | FN16: 554219.8 | FP16: 566387.7 | FR16: 579563.1 | FT16: 591266 | FV16: 558482.5 | FX16: 583050.7 | FZ16: 593126.1 | GB16: 604208.9 | GD16: 584910.8 | GF16: 587158.4 | GH16: 604828.9 | GJ16: 614516.7 | GL16: 592041 | GN16: 598163.7 | GP16: 618081.8 | GR16: 629009.7 | GT16: 617849.3 | GV16: 620949.4 | GX16: 635054.9 | GZ16: 639240 | HB16: 634124.8 | HD16: 632032.3 | HF16: 645672.7 | HH16: 650477.9 | HJ16: 623817 | HL16: 635829.9 | HN16: 651175.4 | HP16: 652880.4 | HR16: 621414.4 | HT16: 626917.1 | HV16: 649857.8 | HX16: 651795.4 | HZ16: 632807.3 | IB16: 644510.2 | ID16: 652802.9 | IF16: 660010.7 | IH16: 631644.8 | IJ16: 652105.4 | IL16: 660243.2 | IN16: 668923.4 | IP16: 658693.1 | IR16: 669931 | IT16: 685664 | IV16: 701862 | IX16: 687136.5 | IZ16: 693646.7 | JB16: 706512.1 | JD16: 719765 | JF16: 701164.4 | JH16: 715347.4 | JJ16: 713719.8 | JL16: 703722 | JN16: 650167.8 | JP16: 653035.4 | JR16: 670551 | JT16: 683881.4 | JV16: 672333.5 | JX16: 686671.5 | JZ16: 703567 | KB16: 717129.9 | KD16: 710542.2 | KF16: 713564.8 | KH16: 727282.8 | KJ16: 732552.9 | KL16: 723097.6 | KN16: 716432.4 | KP16: 727127.8 | KR16: 731855.4 | KT16: 711084.8 | KV16: 722477.6 | KX16: 736428 | KZ16: 742008.2 | LB16: 735730.5 | LD16: 731932.9 | LF16: 750301 | LH16: 759368.8 | LJ16: 741930.7 | LL16: 744023.3 | LN16: 761073.8 | LP16: 773241.7 | LR16: 757431.2 | LT16: 771691.7 | LV16: 774946.8 | LX16: 785642.1 | LZ16: 785564.6 | MB16: 781922 | MD16: 799127.5 | MF16: 812845.4 | MH16: 799282.5 | MJ16: 799980 | ML16: 801685.1 | MN16: 817185.6 | MP16: 806722.7 | MR16: 798740 | MT16: 815635.5 | MV16: 818968.1 | MX16: 797655 | MZ16: 709767.2 | NB16: 786572.1 | ND16: 806102.7 | NF16: 785642.1 | NH16: 792927.3 | NJ16: 815480.5 | NL16: 832143.5 | NN16: 822688.2 | NO16: p | NP16: 810365.4 | NQ16: p | NR16: 827338.4 | NS16: p | NT16: 835553.6 | NU16: p | NV16: 826563.4 | NW16: p | NX16: 801917.6 | NY16: p | NZ16: 815790.5 | OA16: p | OB16: 834158.6 | OC16: p | OD16: 818038.1 | OE16: p | OF16: 806025.2 | OG16: p | OH16: 815945.5 | OI16: p | OJ16: 819510.6 | OK16: p | OL16: 813388 | OM16: p | ON16: 800290 | OO16: p | OP16: :
A17: Estonia | B17: : | D17: : | F17: : | H17: : | J17: : | L17: : | N17: : | P17: : | R17: : | T17: : | V17: : | X17: : | Z17: : | AB17: : | AD17: : | AF17: : | AH17: : | AJ17: : | AL17: : | AN17: : | AP17: : | AR17: : | AT17: : | AV17: : | AX17: : | AZ17: : | BB17: : | BD17: : | BF17: : | BH17: : | BJ17: : | BL17: : | BN17: : | BP17: : | BR17: : | BT17: : | BV17: : | BX17: : | BZ17: : | CB17: : | CD17: : | CF17: : | CH17: : | CJ17: : | CL17: : | CN17: : | CP17: : | CR17: : | CT17: : | CV17: : | CX17: : | CZ17: : | DB17: : | DD17: : | DF17: : | DH17: : | DJ17: : | DL17: : | DN17: : | DP17: : | DR17: : | DT17: : | DV17: : | DX17: : | DZ17: : | EB17: : | ED17: : | EF17: : | EH17: : | EJ17: : | EL17: : | EN17: : | EP17: : | ER17: : | ET17: : | EV17: : | EX17: : | EZ17: : | FB17: : | FD17: : | FF17: 2159.1 | FH17: 2406 | FJ17: 2340.6 | FL17: 2454.4 | FN17: 2238.8 | FP17: 2498.7 | FR17: 2470.9 | FT17: 2611.5 | FV17: 2438.7 | FX17: 2808.3 | FZ17: 2786.3 | GB17: 2964.2 | GD17: 2758.4 | GF17: 3033.2 | GH17: 2941.1 | GJ17: 2974.6 | GL17: 2753 | GN17: 3024.1 | GP17: 2879.2 | GR17: 3058.8 | GT17: 2941.8 | GV17: 3338.9 | GX17: 3137.3 | GZ17: 3380.8 | HB17: 3134.6 | HD17: 3470.5 | HF17: 3347.5 | HH17: 3551.3 | HJ17: 3205.5 | HL17: 3743.7 | HN17: 3636.3 | HP17: 3810.3 | HR17: 3532.5 | HT17: 3937.5 | HV17: 3865.5 | HX17: 4165.9 | HZ17: 3787.6 | IB17: 4186.4 | ID17: 4140.8 | IF17: 4356.5 | IH17: 4119.2 | IJ17: 4536 | IL17: 4544.4 | IN17: 4842.6 | IP17: 4506.5 | IR17: 4960.6 | IT17: 4972.9 | IV17: 5278.7 | IX17: 4901.3 | IZ17: 5423.2 | JB17: 5318.1 | JD17: 5461.7 | JF17: 4777.7 | JH17: 5387.3 | JJ17: 5314.5 | JL17: 4990.7 | JN17: 4207.5 | JP17: 4446.4 | JR17: 4244.8 | JT17: 4446.2 | JV17: 4156.2 | JX17: 4582 | JZ17: 4499.3 | KB17: 4739.2 | KD17: 4565.1 | KF17: 4968.3 | KH17: 4910 | KJ17: 4955.9 | KL17: 4673.3 | KN17: 5115.3 | KP17: 5059.5 | KR17: 5166.3 | KT17: 4906.8 | KV17: 5211.1 | KX17: 5127 | KZ17: 5118.9 | LB17: 4906.6 | LD17: 5333.7 | LF17: 5295.6 | LH17: 5477.5 | LJ17: 4931.4 | LL17: 5467.1 | LN17: 5426.8 | LP17: 5525.7 | LR17: 5188.9 | LT17: 5556.7 | LV17: 5512 | LX17: 5693.4 | LZ17: 5467.3 | MB17: 5961.1 | MD17: 5800.9 | MF17: 6148.6 | MH17: 5646.2 | MJ17: 6147.9 | ML17: 6082.8 | MN17: 6458.3 | MP17: 5861.2 | MR17: 6312.1 | MT17: 6341 | MV17: 6583.8 | MX17: 5950.7 | MZ17: 5780 | NB17: 6169 | ND17: 6520.2 | NF17: 6185.8 | NH17: 6562.4 | NJ17: 6613.4 | NL17: 6977.5 | NN17: 6372.4 | NP17: 6492.1 | NR17: 6588.4 | NT17: 6685.8 | NV17: 6075 | NX17: 6325.8 | NZ17: 6397.8 | OB17: 6562.6 | OD17: 6000.7 | OF17: 6352 | OH17: 6315.6 | OJ17: 6484 | OL17: 5964.4 | ON17: 6371.1 | OP17: :
A18: Ireland | B18: : | D18: : | F18: : | H18: : | J18: : | L18: : | N18: : | P18: : | R18: : | T18: : | V18: : | X18: : | Z18: : | AB18: : | AD18: : | AF18: : | AH18: : | AJ18: : | AL18: : | AN18: : | AP18: : | AR18: : | AT18: : | AV18: : | AX18: : | AZ18: : | BB18: : | BD18: : | BF18: : | BH18: : | BJ18: : | BL18: : | BN18: : | BP18: : | BR18: : | BT18: : | BV18: : | BX18: : | BZ18: : | CB18: : | CD18: : | CF18: : | CH18: : | CJ18: : | CL18: : | CN18: : | CP18: : | CR18: : | CT18: : | CV18: : | CX18: : | CZ18: : | DB18: : | DD18: : | DF18: : | DH18: : | DJ18: : | DL18: : | DN18: : | DP18: : | DR18: : | DT18: : | DV18: : | DX18: : | DZ18: : | EB18: : | ED18: : | EF18: : | EH18: : | EJ18: : | EL18: : | EN18: : | EP18: : | ER18: : | ET18: : | EV18: : | EX18: : | EZ18: : | FB18: : | FD18: : | FF18: 24515.1 | FH18: 25897.2 | FJ18: 24898.1 | FL18: 25156.7 | FN18: 26184.9 | FP18: 27413.8 | FR18: 26001.5 | FT18: 26901.1 | FV18: 28203.8 | FX18: 29879.6 | FZ18: 29653.1 | GB18: 29905.7 | GD18: 31484.7 | GF18: 32120.1 | GH18: 32393.4 | GJ18: 32127.6 | GL18: 33534.4 | GN18: 34422.3 | GP18: 34577.6 | GR18: 36321.7 | GT18: 35360.9 | GV18: 37617.1 | GX18: 37382.4 | GZ18: 39829.8 | HB18: 38249.7 | HD18: 39603.7 | HF18: 38087.9 | HH18: 39970.6 | HJ18: 39867 | HL18: 42470.7 | HN18: 40595 | HP18: 42478 | HR18: 40490.2 | HT18: 42670.9 | HV18: 40354.5 | HX18: 44040.9 | HZ18: 43312.1 | IB18: 44988.6 | ID18: 42369.7 | IF18: 45597.4 | IH18: 45950.6 | IJ18: 47347.8 | IL18: 45456.2 | IN18: 48250.6 | IP18: 47829.1 | IR18: 49804.8 | IT18: 48055.6 | IV18: 49900.2 | IX18: 52331.4 | IZ18: 52827.8 | JB18: 51881.3 | JD18: 53842.7 | JF18: 52596.5 | JH18: 52752 | JJ18: 51331.5 | JL18: 49469.2 | JN18: 49080.3 | JP18: 49587.7 | JR18: 47522.9 | JT18: 46818.7 | JV18: 48986.3 | JX18: 48921.7 | JZ18: 48624.3 | KB18: 49948.2 | KD18: 49176.8 | KF18: 51323.5 | KH18: 49830.1 | KJ18: 50873.7 | KL18: 49042 | KN18: 49282.3 | KP18: 48189.3 | KR18: 49078.8 | KT18: 47900.7 | KV18: 49853.4 | KX18: 50459.9 | KZ18: 51646.6 | LB18: 51926.8 | LD18: 55086.9 | LF18: 54263.6 | LH18: 55834.9 | LJ18: 67268.5 | LL18: 64142.8 | LN18: 65817.3 | LP18: 68734.7 | LR18: 65788.1 | LT18: 65045 | LV18: 63825.9 | LX18: 73915.9 | LZ18: 68621 | MB18: 68999.4 | MD18: 73816.3 | MF18: 77870.9 | MH18: 74888.6 | MJ18: 78382 | ML18: 80455.6 | MN18: 82624.3 | MP18: 77894.8 | MR18: 82471.2 | MT18: 85149.1 | MV18: 87524.5 | MX18: 88256.5 | MZ18: 83497.9 | NB18: 93232.9 | ND18: 93677.9 | NF18: 98333.6 | NH18: 101618.8 | NJ18: 108619.7 | NL18: 109194.8 | NN18: 106546.1 | NP18: 110103.1 | NR18: 117921.4 | NT18: 119889.5 | NV18: 108048.6 | NX18: 112531.9 | NZ18: 113360.6 | OB18: 111073.2 | OD18: 106339.2 | OF18: 108960.2 | OH18: 119983.3 | OJ18: 121363.4 | OL18: 126390.3 | ON18: 126585.7 | OP18: :
A19: Greece | B19: : | D19: : | F19: : | H19: : | J19: : | L19: : | N19: : | P19: : | R19: : | T19: : | V19: : | X19: : | Z19: : | AB19: : | AD19: : | AF19: : | AH19: : | AJ19: : | AL19: : | AN19: : | AP19: : | AR19: : | AT19: : | AV19: : | AX19: : | AZ19: : | BB19: : | BD19: : | BF19: : | BH19: : | BJ19: : | BL19: : | BN19: : | BP19: : | BR19: : | BT19: : | BV19: : | BX19: : | BZ19: : | CB19: : | CD19: : | CF19: : | CH19: : | CJ19: : | CL19: : | CN19: : | CP19: : | CR19: : | CT19: : | CV19: : | CX19: : | CZ19: : | DB19: : | DD19: : | DF19: : | DH19: : | DJ19: : | DL19: : | DN19: : | DP19: : | DR19: : | DT19: : | DV19: : | DX19: : | DZ19: : | EB19: : | ED19: : | EF19: : | EH19: : | EJ19: : | EL19: : | EN19: : | EP19: : | ER19: : | ET19: : | EV19: : | EX19: : | EZ19: : | FB19: : | FD19: : | FF19: 30668.5 | FH19: 31323.8 | FJ19: 34074.9 | FL19: 35140.6 | FN19: 31186.6 | FP19: 31478.2 | FR19: 34390 | FT19: 35249.6 | FV19: 31740.1 | FX19: 32587.5 | FZ19: 35723.2 | GB19: 36625.2 | GD19: 33791.3 | GF19: 34203.2 | GH19: 36864.2 | GJ19: 37607.6 | GL19: 34057 | GN19: 34594.9 | GP19: 37315.2 | GR19: 38542.4 | GT19: 35292.6 | GV19: 36022.8 | GX19: 38977.7 | GZ19: 39966.3 | HB19: 37338 | HD19: 37471.6 | HF19: 40399.8 | HH19: 40972.7 | HJ19: 38452.5 | HL19: 40005.5 | HN19: 42360 | HP19: 42723.1 | HR19: 40886.5 | HT19: 42495 | HV19: 44691.1 | HX19: 45534.8 | HZ19: 44045.3 | IB19: 45026.4 | ID19: 47556.7 | IF19: 47738.3 | IH19: 44118.9 | IJ19: 46003.4 | IL19: 47981.1 | IN19: 48230.4 | IP19: 46375.3 | IR19: 48562 | IT19: 49731 | IV19: 51437.7 | IX19: 47687.2 | IZ19: 51361.4 | JB19: 51774.1 | JD19: 51085.5 | JF19: 48710.7 | JH19: 50768.8 | JJ19: 51680 | JL19: 51341.1 | JN19: 46343 | JP19: 49147.9 | JR19: 50257 | JT19: 50099 | JV19: 45987 | JX19: 46645.2 | JZ19: 45887.7 | KB19: 45902.3 | KD19: 41441.1 | KF19: 42933.2 | KH19: 42956.9 | KJ19: 40724 | KL19: 37798.8 | KN19: 39176.2 | KP19: 39852.2 | KR19: 39130.6 | KT19: 35742.9 | KV19: 38221.6 | KX19: 39857.8 | KZ19: 39538.8 | LB19: 36083.4 | LD19: 38333.8 | LF19: 39907.3 | LH19: 39213.7 | LJ19: 36339 | LL19: 38389.2 | LN19: 39213 | LP19: 39607.9 | LR19: 35827.8 | LT19: 38135.8 | LV19: 39840.2 | LX19: 39212.5 | LZ19: 36461.2 | MB19: 38853.9 | MD19: 41710.2 | MF19: 39427.9 | MH19: 36925.1 | MJ19: 39815.3 | ML19: 42186.3 | MN19: 40226.9 | MP19: 37242.6 | MR19: 40725.7 | MT19: 43436.7 | MV19: 40568.5 | MX19: 36381.8 | MZ19: 34421.3 | NB19: 38977 | ND19: 37456.2 | NF19: 35806.8 | NH19: 38839 | NJ19: 43570.7 | NL19: 40982.9 | NN19: 38041 | NO19: p | NP19: 41380 | NQ19: p | NR19: 45546.1 | NS19: p | NT19: 42662.9 | NU19: p | NV19: 39171.5 | NW19: p | NX19: 42380.5 | NY19: p | NZ19: 46146.6 | OA19: p | OB19: 43621.8 | OC19: p | OD19: 39428.1 | OE19: p | OF19: 43346.8 | OG19: p | OH19: 47054 | OI19: p | OJ19: 44573.5 | OK19: p | OL19: 39798.7 | OM19: p | ON19: 43956.5 | OO19: p | OP19: :
A20: Spain | B20: : | D20: : | F20: : | H20: : | J20: : | L20: : | N20: : | P20: : | R20: : | T20: : | V20: : | X20: : | Z20: : | AB20: : | AD20: : | AF20: : | AH20: : | AJ20: : | AL20: : | AN20: : | AP20: : | AR20: : | AT20: : | AV20: : | AX20: : | AZ20: : | BB20: : | BD20: : | BF20: : | BH20: : | BJ20: : | BL20: : | BN20: : | BP20: : | BR20: : | BT20: : | BV20: : | BX20: : | BZ20: : | CB20: : | CD20: : | CF20: : | CH20: : | CJ20: : | CL20: : | CN20: : | CP20: : | CR20: : | CT20: : | CV20: : | CX20: : | CZ20: : | DB20: : | DD20: : | DF20: : | DH20: : | DJ20: : | DL20: : | DN20: : | DP20: : | DR20: : | DT20: : | DV20: : | DX20: : | DZ20: : | EB20: : | ED20: : | EF20: : | EH20: : | EJ20: : | EL20: : | EN20: : | EP20: : | ER20: : | ET20: : | EV20: : | EX20: : | EZ20: : | FB20: : | FD20: : | FF20: 166854 | FH20: 177681 | FJ20: 171387 | FL20: 184500 | FN20: 170933 | FP20: 181371 | FR20: 176526 | FT20: 189717 | FV20: 174925 | FX20: 186936 | FZ20: 182815 | GB20: 198201 | GD20: 182845 | GF20: 194456 | GH20: 189782 | GJ20: 204415 | GL20: 190513 | GN20: 202887 | GP20: 198596 | GR20: 212910 | GT20: 202145 | GV20: 214117 | GX20: 208053 | GZ20: 223309 | HB20: 211152 | HD20: 222279 | HF20: 216148 | HH20: 231702 | HJ20: 216382 | HL20: 229457 | HN20: 221505 | HP20: 237526 | HR20: 224187 | HT20: 234416 | HV20: 227093 | HX20: 243270 | HZ20: 229073 | IB20: 241346 | ID20: 234453 | IF20: 250125 | IH20: 235716 | IJ20: 249937 | IL20: 242190 | IN20: 259183 | IP20: 246568 | IR20: 259522 | IT20: 251855 | IV20: 270364 | IX20: 256126 | IZ20: 269941 | JB20: 261776 | JD20: 281295 | JF20: 262135 | JH20: 275629 | JJ20: 265177 | JL20: 277994 | JN20: 251881 | JP20: 264701 | JR20: 257387 | JT20: 271660 | JV20: 251629 | JX20: 264234 | JZ20: 256990 | KB20: 270943 | KD20: 252852 | KF20: 264476 | KH20: 256911 | KJ20: 266933 | KL20: 248046 | KN20: 256313 | KP20: 249817 | KR20: 257974 | KT20: 241062 | KV20: 253579 | KX20: 247885 | KZ20: 256704 | LB20: 242484 | LD20: 254858 | LF20: 251054 | LH20: 261638 | LJ20: 249458 | LL20: 264128 | LN20: 260712 | LP20: 271463 | LR20: 257526 | LT20: 271762 | LV20: 267704 | LX20: 276537 | LZ20: 263405 | MB20: 280732 | MD20: 276020 | MF20: 285848 | MH20: 270370 | MJ20: 287948 | ML20: 281557 | MN20: 293267 | MP20: 278225 | MR20: 293438 | MT20: 286907 | MV20: 298054 | MX20: 267656 | MZ20: 229779 | NB20: 261804 | ND20: 271725 | NF20: 257178 | NH20: 273085 | NJ20: 275294 | NL20: 290180 | NN20: 277039 | NO20: p | NP20: 294469 | NQ20: p | NR20: 294286 | NS20: p | NT20: 305666 | NU20: p | NV20: 289116 | NW20: p | NX20: 300649 | NY20: p | NZ20: 299599 | OA20: p | OB20: 312868 | OC20: p | OD20: 298454 | OE20: p | OF20: 314230 | OG20: p | OH20: 311632 | OI20: p | OJ20: 324895 | OK20: p | OL20: 307256 | OM20: p | ON20: 323648 | OO20: p | OP20: 321488 | OQ20: p
A21: France | B21: : | D21: : | F21: : | H21: : | J21: : | L21: : | N21: : | P21: : | R21: : | T21: : | V21: : | X21: : | Z21: : | AB21: : | AD21: : | AF21: : | AH21: : | AJ21: : | AL21: : | AN21: : | AP21: 270738.9 | AR21: 272973.9 | AT21: 257428.8 | AV21: 279792 | AX21: 270574.2 | AZ21: 275965.4 | BB21: 261773.2 | BD21: 286398.3 | BF21: 277775.5 | BH21: 283707.6 | BJ21: 267304.8 | BL21: 291361.3 | BN21: 282995.3 | BP21: 286651.5 | BR21: 270513.2 | BT21: 294536.4 | BV21: 287864.7 | BX21: 289667 | BZ21: 276769.1 | CB21: 299455.2 | CD21: 290274.4 | CF21: 294313.5 | CH21: 282316.3 | CJ21: 304484.2 | CL21: 295336.1 | CN21: 302288.5 | CP21: 288026 | CR21: 310636 | CT21: 300542.9 | CV21: 306045.8 | CX21: 294411.8 | CZ21: 321188.3 | DB21: 314960.2 | DD21: 320721.6 | DF21: 308632.4 | DH21: 333340.4 | DJ21: 328786.7 | DL21: 335142.9 | DN21: 322694.5 | DP21: 350804.8 | DR21: 340894.8 | DT21: 346252.6 | DV21: 333830.7 | DX21: 355861.6 | DZ21: 345759.8 | EB21: 350086.9 | ED21: 338671.9 | EF21: 360153.2 | EH21: 353999.2 | EJ21: 356780.1 | EL21: 344741.9 | EN21: 364411.9 | EP21: 352388.1 | ER21: 356631.9 | ET21: 343922.2 | EV21: 362705.8 | EX21: 356230.6 | EZ21: 363520.3 | FB21: 351150 | FD21: 374015.2 | FF21: 369722.2 | FH21: 372741.9 | FJ21: 358457.8 | FL21: 379621.7 | FN21: 374511.7 | FP21: 377401.4 | FR21: 365361.7 | FT21: 384981.5 | FV21: 377300.3 | FX21: 387942.2 | FZ21: 375579.6 | GB21: 399200.8 | GD21: 394224 | GF21: 399785.6 | GH21: 389336 | GJ21: 410893.8 | GL21: 403711.1 | GN21: 411748.5 | GP21: 403641.3 | GR21: 429622.3 | GT21: 423772.4 | GV21: 428949.2 | GX21: 418321.5 | GZ21: 445760.7 | HB21: 436739.3 | HD21: 436797.9 | HF21: 425854.6 | HH21: 449720 | HJ21: 438664.1 | HL21: 441486.8 | HN21: 432734.1 | HP21: 454217.8 | HR21: 443303.4 | HT21: 441941.7 | HV21: 435860.1 | HX21: 461801.8 | HZ21: 455097.5 | IB21: 459424.1 | ID21: 449393.4 | IF21: 473800.9 | IH21: 461426.9 | IJ21: 469525.2 | IL21: 457476.8 | IN21: 481281.4 | IP21: 472725.6 | IR21: 481819 | IT21: 469553.3 | IV21: 496676.4 | IX21: 486699.8 | IZ21: 493423.8 | JB21: 483349.7 | JD21: 508202.8 | JF21: 494603.7 | JH21: 500336.9 | JJ21: 486533.4 | JL21: 502679.1 | JN21: 475478.3 | JP21: 481973.8 | JR21: 475443.8 | JT21: 499280.5 | JV21: 480941.8 | JX21: 492505.6 | JZ21: 484819.8 | KB21: 508582.9 | KD21: 497731.6 | KF21: 505444.5 | KH21: 495250.8 | KJ21: 518272.4 | KL21: 504069.9 | KN21: 504984.8 | KP21: 496560.2 | KR21: 519090 | KT21: 501591.4 | KV21: 511681.4 | KX21: 503008.5 | KZ21: 525116.4 | LB21: 508829.6 | LD21: 515416.2 | LF21: 510287.4 | LH21: 531353.9 | LJ21: 514822.6 | LL21: 520197.6 | LN21: 511682.2 | LP21: 536113.7 | LR21: 518393.5 | LT21: 527701.8 | LV21: 511679.5 | LX21: 539198.5 | LZ21: 527614 | MB21: 533105.3 | MD21: 523262.5 | MF21: 553989.5 | MH21: 535812 | MJ21: 540283.4 | ML21: 532562.9 | MN21: 564008.7 | MP21: 547358.5 | MR21: 555289.2 | MT21: 546875.7 | MV21: 568898.3 | MX21: 521513.8 | MZ21: 462262 | NB21: 522688.9 | ND21: 550080.5 | NF21: 528944.5 | NH21: 541982.4 | NJ21: 544728.2 | NL21: 575447.4 | NN21: 554257.8 | NP21: 564375.2 | NR21: 555221.7 | NT21: 582414 | NV21: 567630 | NX21: 574415.3 | NZ21: 563933 | OB21: 595304.8 | OD21: 579762.1 | OF21: 581283.1 | OH21: 575493.1 | OJ21: 600118.8 | OL21: 579811.7 | ON21: 585439.5 | OP21: 579140.3
A22: Croatia | B22: : | D22: : | F22: : | H22: : | J22: : | L22: : | N22: : | P22: : | R22: : | T22: : | V22: : | X22: : | Z22: : | AB22: : | AD22: : | AF22: : | AH22: : | AJ22: : | AL22: : | AN22: : | AP22: : | AR22: : | AT22: : | AV22: : | AX22: : | AZ22: : | BB22: : | BD22: : | BF22: : | BH22: : | BJ22: : | BL22: : | BN22: : | BP22: : | BR22: : | BT22: : | BV22: : | BX22: : | BZ22: : | CB22: : | CD22: : | CF22: : | CH22: : | CJ22: : | CL22: : | CN22: : | CP22: : | CR22: : | CT22: : | CV22: : | CX22: : | CZ22: : | DB22: : | DD22: : | DF22: : | DH22: : | DJ22: : | DL22: : | DN22: : | DP22: : | DR22: : | DT22: : | DV22: : | DX22: : | DZ22: : | EB22: : | ED22: : | EF22: : | EH22: : | EJ22: : | EL22: : | EN22: : | EP22: : | ER22: : | ET22: : | EV22: : | EX22: : | EZ22: : | FB22: : | FD22: : | FF22: 6087.7 | FH22: 6663.1 | FJ22: 7035 | FL22: 6857.6 | FN22: 6512.7 | FP22: 7096.1 | FR22: 7519.1 | FT22: 7141.3 | FV22: 6557.1 | FX22: 7563.4 | FZ22: 8561.5 | GB22: 7560.8 | GD22: 6787.7 | GF22: 7701.4 | GH22: 8788.6 | GJ22: 7648.5 | GL22: 6940.4 | GN22: 7765.7 | GP22: 8619.9 | GR22: 7508.9 | GT22: 7125.6 | GV22: 7760.9 | GX22: 8807.9 | GZ22: 7835.2 | HB22: 7323.7 | HD22: 8109.3 | HF22: 9139 | HH22: 8085.1 | HJ22: 7635.5 | HL22: 8418.2 | HN22: 9762.3 | HP22: 8573.7 | HR22: 8095.3 | HT22: 9033.8 | HV22: 10335.9 | HX22: 8959 | HZ22: 8507.6 | IB22: 9421.7 | ID22: 10733.7 | IF22: 9303.2 | IH22: 8692.3 | IJ22: 9899.8 | IL22: 11263.1 | IN22: 9715.9 | IP22: 9208.8 | IR22: 10261.7 | IT22: 11808.3 | IV22: 10151.7 | IX22: 9785.1 | IZ22: 10826.7 | JB22: 12364.8 | JD22: 10495.3 | JF22: 10120.4 | JH22: 11162.7 | JJ22: 12474.6 | JL22: 10580.4 | JN22: 9491.9 | JP22: 10466.4 | JR22: 11653.2 | JT22: 10215.4 | JV22: 9109.2 | JX22: 10160.1 | JZ22: 11630.3 | KB22: 10160.6 | KD22: 9065.9 | KF22: 10261.9 | KH22: 11718.6 | KJ22: 10107 | KL22: 8794.9 | KN22: 9891.2 | KP22: 11359.1 | KR22: 9745.9 | KT22: 8690.5 | KV22: 9885.8 | KX22: 11348.5 | KZ22: 9673.4 | LB22: 8645.4 | LD22: 9795.4 | LF22: 11209.9 | LH22: 9691 | LJ22: 8713.3 | LL22: 9993.9 | LN22: 11576.6 | LP22: 9945.6 | LR22: 9004.3 | LT22: 10297.5 | LV22: 11994.6 | LX22: 10343.6 | LZ22: 9270.6 | MB22: 10590.7 | MD22: 12389.5 | MF22: 10556.4 | MH22: 9473.9 | MJ22: 10852.7 | ML22: 12674.6 | MN22: 10874 | MP22: 9916.5 | MR22: 11250 | MT22: 13042.7 | MV22: 11083.5 | MX22: 9855.3 | MZ22: 9706.4 | NB22: 11757 | ND22: 10679.4 | NF22: 10172.8 | NH22: 11413.5 | NJ22: 13463.3 | NL22: 11860.2 | NN22: 10968.2 | NP22: 12652.3 | NR22: 14561 | NT22: 12659.5 | NV22: 11347.8 | NX22: 13116 | NZ22: 15123.2 | OB22: 13296 | OD22: 11675.9 | OE22: p | OF22: 13548.1 | OG22: p | OH22: 15651.1 | OI22: p | OJ22: 13714.1 | OK22: p | OL22: 12035.2 | OM22: p | ON22: 14018 | OO22: p | OP22: :
A23: Italy | B23: : | D23: : | F23: : | H23: : | J23: : | L23: : | N23: : | P23: : | R23: : | T23: : | V23: : | X23: : | Z23: : | AB23: : | AD23: : | AF23: : | AH23: : | AJ23: : | AL23: : | AN23: : | AP23: : | AR23: : | AT23: : | AV23: : | AX23: : | AZ23: : | BB23: : | BD23: : | BF23: : | BH23: : | BJ23: : | BL23: : | BN23: : | BP23: : | BR23: : | BT23: : | BV23: : | BX23: : | BZ23: : | CB23: : | CD23: : | CF23: : | CH23: : | CJ23: : | CL23: : | CN23: : | CP23: : | CR23: : | CT23: : | CV23: : | CX23: : | CZ23: : | DB23: : | DD23: : | DF23: : | DH23: : | DJ23: : | DL23: : | DN23: : | DP23: : | DR23: : | DT23: : | DV23: : | DX23: : | DZ23: : | EB23: : | ED23: : | EF23: : | EH23: : | EJ23: : | EL23: : | EN23: : | EP23: : | ER23: : | ET23: : | EV23: : | EX23: : | EZ23: : | FB23: : | FD23: : | FF23: : | FH23: : | FJ23: : | FL23: : | FN23: 341131 | FP23: 355899.6 | FR23: 351277.1 | FT23: 366092.2 | FV23: 338924.2 | FX23: 362360.7 | FZ23: 357254.4 | GB23: 379197.9 | GD23: 349570.5 | GF23: 368991.9 | GH23: 363991.9 | GJ23: 378780.2 | GL23: 352208.5 | GN23: 371381.9 | GP23: 368681.6 | GR23: 392299.5 | GT23: 369473.5 | GV23: 387314.3 | GX23: 381706.3 | GZ23: 403758.8 | HB23: 381645.8 | HD23: 397820.6 | HF23: 386544.5 | HH23: 405817.9 | HJ23: 378868.4 | HL23: 397573.3 | HN23: 390554 | HP23: 410763.4 | HR23: 380587.2 | HT23: 397069.7 | HV23: 390192.9 | HX23: 410551.3 | HZ23: 384918.5 | IB23: 405189.1 | ID23: 398752.3 | IF23: 415687.7 | IH23: 385331.6 | IJ23: 408909.4 | IL23: 404025.1 | IN23: 418872 | IP23: 396918.2 | IR23: 415435.7 | IT23: 409184.8 | IV23: 426894.5 | IX23: 405257.9 | IZ23: 424252.9 | JB23: 416539.6 | JD23: 428645.5 | JF23: 410006 | JH23: 423822.5 | JJ23: 414162.3 | JL23: 412886.1 | JN23: 378719.3 | JP23: 392853.8 | JR23: 394423.4 | JT23: 403047.1 | JV23: 381942.1 | JX23: 401759.3 | JZ23: 401069.7 | KB23: 412633.7 | KD23: 391818.3 | KF23: 408068 | KH23: 403847.9 | KJ23: 406167.6 | KL23: 383299.3 | KN23: 394959.4 | KP23: 391099.4 | KR23: 395083.9 | KT23: 371195.5 | KV23: 386922.1 | KX23: 388888.5 | KZ23: 393872.5 | LB23: 371711.1 | LD23: 386670.1 | LF23: 388688.3 | LH23: 392736.8 | LJ23: 372958 | LL23: 389412.1 | LN23: 391961.9 | LP23: 399827 | LR23: 377742.1 | LT23: 394751.6 | LV23: 397618.1 | LX23: 405293.8 | LZ23: 387731.2 | MB23: 402082.1 | MD23: 402592.3 | MF23: 412029.8 | MH23: 390860.9 | MJ23: 407031.3 | ML23: 406346.6 | MN23: 416103.3 | MP23: 393006.5 | MR23: 410150.3 | MT23: 410864.9 | MV23: 417706 | MX23: 371667.6 | MZ23: 337964.6 | NB23: 389693.8 | ND23: 396996.3 | NF23: 381579.7 | NH23: 403646.5 | NJ23: 416930.5 | NL23: 428313.1 | NN23: 409945.6 | NP23: 430642.9 | NR23: 432624.5 | NT23: 437796.2 | NV23: 421358.1 | NX23: 431932.3 | NZ23: 433858.4 | OB23: 440505.3 | OD23: 422807.8 | OF23: 434773.2 | OH23: 436927.7 | OJ23: 444706.6 | OL23: 423664.4 | ON23: 435880.2 | OP23: :
A24: Cyprus | B24: : | D24: : | F24: : | H24: : | J24: : | L24: : | N24: : | P24: : | R24: : | T24: : | V24: : | X24: : | Z24: : | AB24: : | AD24: : | AF24: : | AH24: : | AJ24: : | AL24: : | AN24: : | AP24: : | AR24: : | AT24: : | AV24: : | AX24: : | AZ24: : | BB24: : | BD24: : | BF24: : | BH24: : | BJ24: : | BL24: : | BN24: : | BP24: : | BR24: : | BT24: : | BV24: : | BX24: : | BZ24: : | CB24: : | CD24: : | CF24: : | CH24: : | CJ24: : | CL24: : | CN24: : | CP24: : | CR24: : | CT24: : | CV24: : | CX24: : | CZ24: : | DB24: : | DD24: : | DF24: : | DH24: : | DJ24: : | DL24: : | DN24: : | DP24: : | DR24: : | DT24: : | DV24: : | DX24: : | DZ24: : | EB24: : | ED24: : | EF24: : | EH24: : | EJ24: : | EL24: : | EN24: : | EP24: : | ER24: : | ET24: : | EV24: : | EX24: : | EZ24: : | FB24: : | FD24: : | FF24: : | FH24: : | FJ24: : | FL24: : | FN24: 2488.1 | FP24: 2618.9 | FR24: 2677.2 | FT24: 2658.9 | FV24: 2496.4 | FX24: 2673.3 | FZ24: 2791.9 | GB24: 2757.3 | GD24: 2624.7 | GF24: 2860.6 | GH24: 2987.1 | GJ24: 2901.7 | GL24: 2754.7 | GN24: 2996.4 | GP24: 3109.3 | GR24: 3082 | GT24: 2944.7 | GV24: 3285.5 | GX24: 3247.6 | GZ24: 3177 | HB24: 3018.1 | HD24: 3336 | HF24: 3442.4 | HH24: 3358.6 | HJ24: 3144.1 | HL24: 3468.6 | HN24: 3510 | HP24: 3522.2 | HR24: 3302.5 | HT24: 3479.5 | HV24: 3612 | HX24: 3608.6 | HZ24: 3471.4 | IB24: 3652.9 | ID24: 3794.7 | IF24: 3787.6 | IH24: 3639 | IJ24: 3834.7 | IL24: 3975.2 | IN24: 3971.2 | IP24: 3807.5 | IR24: 4053.6 | IT24: 4148.4 | IV24: 4137.6 | IX24: 4027.4 | IZ24: 4235.3 | JB24: 4342.4 | JD24: 4365.3 | JF24: 4217.9 | JH24: 4448.5 | JJ24: 4500.9 | JL24: 4421.9 | JN24: 4142.9 | JP24: 4352.2 | JR24: 4375.9 | JT24: 4363.8 | JV24: 4211.1 | JX24: 4442.3 | JZ24: 4492.2 | KB24: 4488.9 | KD24: 4277.1 | KF24: 4524.2 | KH24: 4450.5 | KJ24: 4456.2 | KL24: 4204.3 | KN24: 4359.1 | KP24: 4344.1 | KR24: 4190.2 | KT24: 3878.2 | KV24: 4015.5 | KX24: 4094.8 | KZ24: 3982.8 | LB24: 3740 | LD24: 3989.9 | LF24: 4031.5 | LH24: 3926.3 | LJ24: 3765.8 | LL24: 4124.8 | LN24: 4171.7 | LP24: 4136.7 | LR24: 4012.8 | LT24: 4396.5 | LV24: 4433.4 | LX24: 4421.4 | LZ24: 4303.8 | MB24: 4659.2 | MD24: 4664.1 | MF24: 4633 | MH24: 4557.7 | MJ24: 4954.3 | ML24: 4953.8 | MN24: 4960.1 | MP24: 4818.3 | MR24: 5206.7 | MT24: 5327.1 | MV24: 5253.1 | MX24: 4978.2 | MZ24: 4642 | NB24: 5105.3 | ND24: 5233.2 | NF24: 5180.2 | NH24: 5479.8 | NJ24: 5776 | NL24: 5796.1 | NN24: 5756 | NP24: 6006.5 | NR24: 6243.4 | NT24: 6065.7 | NV24: 5976.4 | NX24: 6282.1 | NZ24: 6397.1 | OB24: 6287 | OD24: 6255.2 | OF24: 6503.6 | OH24: 6672.7 | OJ24: 6494.4 | OL24: 6445.6 | ON24: 6740.7 | OP24: :
A25: Latvia | B25: : | D25: : | F25: : | H25: : | J25: : | L25: : | N25: : | P25: : | R25: : | T25: : | V25: : | X25: : | Z25: : | AB25: : | AD25: : | AF25: : | AH25: : | AJ25: : | AL25: : | AN25: : | AP25: : | AR25: : | AT25: : | AV25: : | AX25: : | AZ25: : | BB25: : | BD25: : | BF25: : | BH25: : | BJ25: : | BL25: : | BN25: : | BP25: : | BR25: : | BT25: : | BV25: : | BX25: : | BZ25: : | CB25: : | CD25: : | CF25: : | CH25: : | CJ25: : | CL25: : | CN25: : | CP25: : | CR25: : | CT25: : | CV25: : | CX25: : | CZ25: : | DB25: : | DD25: : | DF25: : | DH25: : | DJ25: : | DL25: : | DN25: : | DP25: : | DR25: : | DT25: : | DV25: : | DX25: : | DZ25: : | EB25: : | ED25: : | EF25: : | EH25: : | EJ25: : | EL25: : | EN25: : | EP25: : | ER25: : | ET25: : | EV25: : | EX25: : | EZ25: : | FB25: : | FD25: : | FF25: 2366.1 | FH25: 2615.3 | FJ25: 2545.7 | FL25: 2805.3 | FN25: 2370 | FP25: 2594 | FR25: 2665.6 | FT25: 2915.3 | FV25: 2519 | FX25: 2942.7 | FZ25: 2943.5 | GB25: 3146.4 | GD25: 2849.8 | GF25: 3167.2 | GH25: 3102.5 | GJ25: 3229.9 | GL25: 2880.8 | GN25: 3101.4 | GP25: 3206.7 | GR25: 3553.4 | GT25: 3023.1 | GV25: 3337.1 | GX25: 3411.4 | GZ25: 3689.1 | HB25: 3144.8 | HD25: 3674.9 | HF25: 3515.8 | HH25: 4010.8 | HJ25: 3289.2 | HL25: 3919.5 | HN25: 3894.5 | HP25: 4375.9 | HR25: 3613.9 | HT25: 4212.7 | HV25: 4256.3 | HX25: 4690.3 | HZ25: 3946.7 | IB25: 4618.3 | ID25: 4584.4 | IF25: 5091 | IH25: 4268.5 | IJ25: 5054.4 | IL25: 5257 | IN25: 5830.6 | IP25: 4769 | IR25: 5698.5 | IT25: 5863.3 | IV25: 6598.9 | IX25: 5432.6 | IZ25: 6360.1 | JB25: 6456.2 | JD25: 6864.5 | JF25: 5656.1 | JH25: 6351.9 | JJ25: 6144.7 | JL25: 6499.6 | JN25: 5052.1 | JP25: 5379.6 | JR25: 5220.9 | JT25: 5615.3 | JV25: 4513.2 | JX25: 5098.6 | JZ25: 5171.5 | KB25: 5574.5 | KD25: 4539.7 | KF25: 5228.9 | KH25: 5395.8 | KJ25: 5730.1 | KL25: 4978.7 | KN25: 5590.4 | KP25: 5749.6 | KR25: 6021 | KT25: 4963.4 | KV25: 5656.7 | KX25: 5900.1 | KZ25: 6136.5 | LB25: 5115 | LD25: 5758.8 | LF25: 5999.6 | LH25: 6195.3 | LJ25: 5221.6 | LL25: 5988.5 | LN25: 6248.4 | LP25: 6426.2 | LR25: 5399.9 | LT25: 6122 | LV25: 6292.3 | LX25: 6548.3 | LZ25: 5570.7 | MB25: 6292.3 | MD25: 6536.4 | MF25: 6790.9 | MH25: 5625 | MJ25: 6580.3 | ML25: 6794.1 | MN25: 7120.4 | MP25: 5718.9 | MR25: 6617.8 | MT25: 6900.7 | MV25: 7046 | MX25: 5726.4 | MZ25: 6007.5 | NB25: 6649.4 | ND25: 6983.7 | NF25: 5803.4 | NH25: 6790.5 | NJ25: 7187.1 | NL25: 7438 | NN25: 6317.5 | NP25: 6970.8 | NR25: 7169.8 | NT25: 7226.4 | NV25: 6614.9 | NX25: 6838.1 | NZ25: 7103.2 | OB25: 6983.4 | OD25: 6510.6 | OF25: 6810.9 | OH25: 7190.9 | OJ25: 6987.4 | OL25: 6592.3 | ON25: 6872.5 | OP25: :
A26: Lithuania | B26: : | D26: : | F26: : | H26: : | J26: : | L26: : | N26: : | P26: : | R26: : | T26: : | V26: : | X26: : | Z26: : | AB26: : | AD26: : | AF26: : | AH26: : | AJ26: : | AL26: : | AN26: : | AP26: : | AR26: : | AT26: : | AV26: : | AX26: : | AZ26: : | BB26: : | BD26: : | BF26: : | BH26: : | BJ26: : | BL26: : | BN26: : | BP26: : | BR26: : | BT26: : | BV26: : | BX26: : | BZ26: : | CB26: : | CD26: : | CF26: : | CH26: : | CJ26: : | CL26: : | CN26: : | CP26: : | CR26: : | CT26: : | CV26: : | CX26: : | CZ26: : | DB26: : | DD26: : | DF26: : | DH26: : | DJ26: : | DL26: : | DN26: : | DP26: : | DR26: : | DT26: : | DV26: : | DX26: : | DZ26: : | EB26: : | ED26: : | EF26: : | EH26: : | EJ26: : | EL26: : | EN26: : | EP26: : | ER26: : | ET26: : | EV26: : | EX26: : | EZ26: : | FB26: : | FD26: : | FF26: 3588.5 | FH26: 3957.5 | FJ26: 4496.1 | FL26: 4326.8 | FN26: 3769.6 | FP26: 4040.5 | FR26: 4856.6 | FT26: 4525 | FV26: 3940.8 | FX26: 4446.5 | FZ26: 5264 | GB26: 4967.5 | GD26: 4368 | GF26: 4905.6 | GH26: 5564.1 | GJ26: 5170.6 | GL26: 4491.4 | GN26: 4959.1 | GP26: 5337.1 | GR26: 5001.1 | GT26: 4681.9 | GV26: 5033.2 | GX26: 5482.3 | GZ26: 5267.8 | HB26: 4997.4 | HD26: 5295.3 | HF26: 5816.7 | HH26: 5682.8 | HJ26: 5229.9 | HL26: 5715.3 | HN26: 6278.5 | HP26: 6033 | HR26: 5797.7 | HT26: 6249.4 | HV26: 6911.5 | HX26: 6752.2 | HZ26: 6206.5 | IB26: 6710.8 | ID26: 7247.7 | IF26: 7217.4 | IH26: 6548.3 | IJ26: 7186.6 | IL26: 7903.2 | IN26: 7861.4 | IP26: 7043.5 | IR26: 7782.7 | IT26: 8443.9 | IV26: 8411 | IX26: 7733 | IZ26: 8683.2 | JB26: 9483.7 | JD26: 9290.7 | JF26: 8280.2 | JH26: 9149.3 | JJ26: 9635.8 | JL26: 9040.2 | JN26: 7124.3 | JP26: 7711.2 | JR26: 8253.2 | JT26: 7659.3 | JV26: 6969.1 | JX26: 7715.9 | JZ26: 8234.6 | KB26: 7959.6 | KD26: 7411.5 | KF26: 8145.2 | KH26: 8843.7 | KJ26: 8431.6 | KL26: 7726.2 | KN26: 8358.3 | KP26: 9346.4 | KR26: 8840.1 | KT26: 8030 | KV26: 8736.2 | KX26: 9682.7 | KZ26: 9209.1 | LB26: 8423.7 | LD26: 9121.9 | LF26: 10001.7 | LH26: 9455.7 | LJ26: 8612.9 | LL26: 9354 | LN26: 10306.9 | LP26: 9777.6 | LR26: 8821.2 | LT26: 9532.2 | LV26: 10538.5 | LX26: 10176.1 | LZ26: 9268.4 | MB26: 9995.6 | MD26: 10979.9 | MF26: 10626.1 | MH26: 9718.7 | MJ26: 10536.3 | ML26: 11464.2 | MN26: 11160.8 | MP26: 10207.5 | MR26: 11024.6 | MT26: 11990.6 | MV26: 11663.1 | MX26: 10517.2 | MZ26: 10544.3 | NB26: 12169.5 | ND26: 11674 | NF26: 10841.4 | NH26: 11540.4 | NJ26: 12926.8 | NL26: 12468 | NN26: 11448 | NP26: 11836.7 | NR26: 13173.3 | NT26: 12496.4 | NV26: 11284.3 | NX26: 12047 | NZ26: 13335.3 | OB26: 12649.8 | OD26: 11648.2 | OF26: 12281.8 | OH26: 13683.7 | OJ26: 13197.1 | OL26: 12027.6 | ON26: 12680 | OP26: :
A27: Luxembourg | B27: : | D27: : | F27: : | H27: : | J27: : | L27: : | N27: : | P27: : | R27: : | T27: : | V27: : | X27: : | Z27: : | AB27: : | AD27: : | AF27: : | AH27: : | AJ27: : | AL27: : | AN27: : | AP27: : | AR27: : | AT27: : | AV27: : | AX27: : | AZ27: : | BB27: : | BD27: : | BF27: : | BH27: : | BJ27: : | BL27: : | BN27: : | BP27: : | BR27: : | BT27: : | BV27: : | BX27: : | BZ27: : | CB27: : | CD27: : | CF27: : | CH27: : | CJ27: : | CL27: : | CN27: : | CP27: : | CR27: : | CT27: : | CV27: : | CX27: : | CZ27: : | DB27: : | DD27: : | DF27: : | DH27: : | DJ27: : | DL27: : | DN27: : | DP27: : | DR27: : | DT27: : | DV27: : | DX27: : | DZ27: : | EB27: : | ED27: : | EF27: : | EH27: : | EJ27: : | EL27: : | EN27: : | EP27: : | ER27: : | ET27: : | EV27: : | EX27: : | EZ27: : | FB27: : | FD27: : | FF27: 6873.8 | FH27: 7063 | FJ27: 6852.4 | FL27: 6919.9 | FN27: 6845.8 | FP27: 7128.3 | FR27: 6836.2 | FT27: 7199.3 | FV27: 6985.7 | FX27: 7455.8 | FZ27: 7332.5 | GB27: 7543.6 | GD27: 7571.2 | GF27: 7914 | GH27: 7779.7 | GJ27: 7987.1 | GL27: 8175.9 | GN27: 8481.9 | GP27: 8413.9 | GR27: 8622.7 | GT27: 8829.2 | GV27: 8945.6 | GX27: 8810.1 | GZ27: 9179.6 | HB27: 9163.7 | HD27: 9222.4 | HF27: 9067.1 | HH27: 9611.6 | HJ27: 9334.1 | HL27: 9773.5 | HN27: 9382.9 | HP27: 9720.7 | HR27: 9525.9 | HT27: 9915 | HV27: 9576.9 | HX27: 10154.6 | HZ27: 10032 | IB27: 10287.4 | ID27: 10002.4 | IF27: 10290.8 | IH27: 9873.9 | IJ27: 10285.6 | IL27: 10177 | IN27: 11153.1 | IP27: 10917.3 | IR27: 11271.3 | IT27: 10872.2 | IV27: 11258.9 | IX27: 11781.5 | IZ27: 12251.6 | JB27: 11719 | JD27: 12173.6 | JF27: 12049.3 | JH27: 12365.9 | JJ27: 11726.1 | JL27: 11566.4 | JN27: 11223.3 | JP27: 11627.5 | JR27: 11410 | JT27: 11871.1 | JV27: 11907.3 | JX27: 12172.8 | JZ27: 11633.7 | KB27: 12102.6 | KD27: 12030.7 | KF27: 12081.9 | KH27: 11842.4 | KJ27: 12039.5 | KL27: 12042.9 | KN27: 12163 | KP27: 11911.5 | KR27: 12537.7 | KT27: 12243.5 | KV27: 12700.7 | KX27: 12430.1 | KZ27: 12790.5 | LB27: 12524 | LD27: 12546.3 | LF27: 12592.8 | LH27: 13528.4 | LJ27: 13159.1 | LL27: 13476.6 | LN27: 13197.3 | LP27: 13723.7 | LR27: 13631.4 | LT27: 14041 | LV27: 13976.7 | LX27: 14626.8 | LZ27: 13693.6 | MB27: 14129.8 | MD27: 14113.9 | MF27: 14849.8 | MH27: 14021 | MJ27: 14314.6 | ML27: 14265.3 | MN27: 14890.5 | MP27: 14246.1 | MR27: 14827.8 | MT27: 14709.3 | MV27: 15333.8 | MX27: 14506.9 | MZ27: 13919.6 | NB27: 14734.4 | ND27: 15432.4 | NF27: 15363 | NH27: 15619.7 | NJ27: 15515 | NL27: 16344.4 | NN27: 15262.2 | NP27: 15485.1 | NR27: 15382.8 | NT27: 15779 | NV27: 15214.7 | NX27: 15594.1 | NZ27: 15418 | OB27: 15591.6 | OD27: 15681.9 | OF27: 15682 | OH27: 15057.1 | OJ27: 15440 | OL27: 15254.8 | OM27: p | ON27: 15549.9 | OO27: p | OP27: :
A28: Hungary | B28: : | D28: : | F28: : | H28: : | J28: : | L28: : | N28: : | P28: : | R28: : | T28: : | V28: : | X28: : | Z28: : | AB28: : | AD28: : | AF28: : | AH28: : | AJ28: : | AL28: : | AN28: : | AP28: : | AR28: : | AT28: : | AV28: : | AX28: : | AZ28: : | BB28: : | BD28: : | BF28: : | BH28: : | BJ28: : | BL28: : | BN28: : | BP28: : | BR28: : | BT28: : | BV28: : | BX28: : | BZ28: : | CB28: : | CD28: : | CF28: : | CH28: : | CJ28: : | CL28: : | CN28: : | CP28: : | CR28: : | CT28: : | CV28: : | CX28: : | CZ28: : | DB28: : | DD28: : | DF28: : | DH28: : | DJ28: : | DL28: : | DN28: : | DP28: : | DR28: : | DT28: : | DV28: : | DX28: : | DZ28: : | EB28: : | ED28: : | EF28: : | EH28: : | EJ28: : | EL28: : | EN28: : | EP28: : | ER28: : | ET28: : | EV28: : | EX28: : | EZ28: : | FB28: : | FD28: : | FF28: 5287993.4 | FH28: 5690937.8 | FJ28: 5807672.5 | FL28: 5939092.9 | FN28: 5322572.6 | FP28: 5747967.8 | FR28: 5848503 | FT28: 6121961.7 | FV28: 5340906.4 | FX28: 5919752.8 | FZ28: 6097560.1 | GB28: 6340159.9 | GD28: 5524837.2 | GF28: 6134792.2 | GH28: 6359346.6 | GJ28: 6578803.2 | GL28: 5633211.2 | GN28: 6257389.4 | GP28: 6544382.3 | GR28: 6880335.8 | GT28: 5934790.4 | GV28: 6548157 | GX28: 6801758.4 | GZ28: 7123990.4 | HB28: 6235053.4 | HD28: 6857718.2 | HF28: 7081212.2 | HH28: 7354542.3 | HJ28: 6525429.8 | HL28: 7194140.9 | HN28: 7407188.5 | HP28: 7731908.3 | HR28: 6732608.1 | HT28: 7488984.5 | HV28: 7731425.6 | HX28: 8087842.1 | HZ28: 7025281.2 | IB28: 7886084.9 | ID28: 8137383.3 | IF28: 8476957.6 | IH28: 7286859.6 | IJ28: 8254035.8 | IL28: 8454663.1 | IN28: 8863167.1 | IP28: 7646670.2 | IR28: 8535983.8 | IT28: 8757346.7 | IV28: 9195510.5 | IX28: 7780938.9 | IZ28: 8546989.1 | JB28: 8750388.1 | JD28: 9150866.1 | JF28: 7893280.4 | JH28: 8757025.1 | JJ28: 8927814.8 | JL28: 8932845.7 | JN28: 7310682.4 | JP28: 8029899.4 | JR28: 8235363.1 | JT28: 8582901.3 | JV28: 7312018.4 | JX28: 8121087.7 | JZ28: 8382662.1 | KB28: 8756335.1 | KD28: 7537866.3 | KF28: 8245907.5 | KH28: 8491108.4 | KJ28: 8952540.6 | KL28: 7518447.5 | KN28: 8155154.2 | KP28: 8398361.6 | KR28: 8710118.8 | KT28: 7493519.9 | KV28: 8320227.8 | KX28: 8736030.1 | KZ28: 9118610.9 | LB28: 7836526 | LD28: 8768572.9 | LF28: 9106454 | LH28: 9502368.8 | LJ28: 8203339.1 | LL28: 9060369.7 | LN28: 9367704 | LP28: 9861493.7 | LR28: 8328334.6 | LT28: 9371487.2 | LV28: 9622766 | LX28: 10111665 | LZ28: 8710627.6 | MB28: 9681352 | MD28: 10006824 | MF28: 10541531 | MH28: 9185485 | MJ28: 10245914 | ML28: 10613921 | MN28: 11173484 | MP28: 9657919.8 | MR28: 10743586 | MT28: 11176054 | MV28: 11665197 | MX28: 9851251.1 | MZ28: 9363521.2 | NB28: 10686154 | ND28: 11348779 | NF28: 9646880.1 | NH28: 11084194 | NJ28: 11421189 | NL28: 12244377 | NN28: 10288970 | NP28: 11780639 | NR28: 11874224 | NT28: 12415274 | NV28: 10221435 | NX28: 11573421 | NZ28: 11993071 | OB28: 12470596 | OD28: 10288602 | OE28: p | OF28: 11704618 | OG28: p | OH28: 11858707 | OI28: p | OJ28: 12483418 | OK28: p | OL28: 10274214 | OM28: p | ON28: 11723295 | OO28: p | OP28: :
A29: Malta | B29: : | D29: : | F29: : | H29: : | J29: : | L29: : | N29: : | P29: : | R29: : | T29: : | V29: : | X29: : | Z29: : | AB29: : | AD29: : | AF29: : | AH29: : | AJ29: : | AL29: : | AN29: : | AP29: : | AR29: : | AT29: : | AV29: : | AX29: : | AZ29: : | BB29: : | BD29: : | BF29: : | BH29: : | BJ29: : | BL29: : | BN29: : | BP29: : | BR29: : | BT29: : | BV29: : | BX29: : | BZ29: : | CB29: : | CD29: : | CF29: : | CH29: : | CJ29: : | CL29: : | CN29: : | CP29: : | CR29: : | CT29: : | CV29: : | CX29: : | CZ29: : | DB29: : | DD29: : | DF29: : | DH29: : | DJ29: : | DL29: : | DN29: : | DP29: : | DR29: : | DT29: : | DV29: : | DX29: : | DZ29: : | EB29: : | ED29: : | EF29: : | EH29: : | EJ29: : | EL29: : | EN29: : | EP29: : | ER29: : | ET29: : | EV29: : | EX29: : | EZ29: : | FB29: : | FD29: : | FF29: : | FH29: : | FJ29: : | FL29: : | FN29: : | FP29: : | FR29: : | FT29: : | FV29: : | FX29: : | FZ29: : | GB29: : | GD29: : | GF29: : | GH29: : | GJ29: : | GL29: : | GN29: : | GP29: : | GR29: : | GT29: 1355.9 | GV29: 1505 | GX29: 1564.6 | GZ29: 1503.3 | HB29: 1363.5 | HD29: 1493.3 | HF29: 1559.3 | HH29: 1433 | HJ29: 1396.6 | HL29: 1517.3 | HN29: 1633.6 | HP29: 1508.9 | HR29: 1462.6 | HT29: 1591.9 | HV29: 1694.9 | HX29: 1578.1 | HZ29: 1461.4 | IB29: 1567.6 | ID29: 1660.8 | IF29: 1571.9 | IH29: 1456.4 | IJ29: 1580.2 | IL29: 1687 | IN29: 1580.1 | IP29: 1491.6 | IR29: 1634.1 | IT29: 1735.7 | IV29: 1619.4 | IX29: 1607 | IZ29: 1724.7 | JB29: 1825.5 | JD29: 1684.8 | JF29: 1708.2 | JH29: 1817.4 | JJ29: 1883.4 | JL29: 1775.8 | JN29: 1709.9 | JP29: 1794.6 | JR29: 1908.2 | JT29: 1812.2 | JV29: 1824.7 | JX29: 1908.7 | JZ29: 2020.6 | KB29: 1886.9 | KD29: 1838.4 | KF29: 1885.4 | KH29: 1961.1 | KJ29: 1886.6 | KL29: 1870.7 | KN29: 1989.1 | KP29: 2080.3 | KR29: 1993 | KT29: 2040.9 | KV29: 2134.8 | KX29: 2236.4 | KZ29: 2134.9 | LB29: 2210.3 | LD29: 2313.9 | LF29: 2438.7 | LH29: 2364 | LJ29: 2377.5 | LL29: 2559.2 | LN29: 2694.9 | LP29: 2546.9 | LR29: 2517.1 | LT29: 2651.4 | LV29: 2795.9 | LX29: 2637.2 | LZ29: 2863.5 | MB29: 3004.4 | MD29: 3112.1 | MF29: 3015.9 | MH29: 3036.2 | MJ29: 3246 | ML29: 3369.7 | MN29: 3238.6 | MP29: 3196.4 | MR29: 3363.8 | MT29: 3477.1 | MV29: 3393.1 | MX29: 3455.4 | MZ29: 3099.7 | NB29: 3323.2 | ND29: 3271.4 | NF29: 3510.6 | NH29: 3630.1 | NJ29: 3912.6 | NL29: 3800.2 | NN29: 3630.5 | NP29: 3795.5 | NR29: 4024.3 | NT29: 3960.8 | NV29: 3971.7 | NX29: 4189.8 | NZ29: 4310.9 | OB29: 4348.4 | OD29: 4206.2 | OF29: 4428.7 | OH29: 4539.4 | OJ29: 4506.1 | OL29: 4406.9 | ON29: 4597.6 | OP29: :
A30: Netherlands | B30: : | D30: : | F30: : | H30: : | J30: : | L30: : | N30: : | P30: : | R30: : | T30: : | V30: : | X30: : | Z30: : | AB30: : | AD30: : | AF30: : | AH30: : | AJ30: : | AL30: : | AN30: : | AP30: : | AR30: : | AT30: : | AV30: : | AX30: : | AZ30: : | BB30: : | BD30: : | BF30: : | BH30: : | BJ30: : | BL30: : | BN30: : | BP30: : | BR30: : | BT30: : | BV30: : | BX30: : | BZ30: : | CB30: : | CD30: : | CF30: : | CH30: : | CJ30: : | CL30: : | CN30: : | CP30: : | CR30: : | CT30: : | CV30: : | CX30: : | CZ30: : | DB30: : | DD30: : | DF30: : | DH30: : | DJ30: : | DL30: : | DN30: : | DP30: : | DR30: : | DT30: : | DV30: : | DX30: : | DZ30: : | EB30: : | ED30: : | EF30: : | EH30: : | EJ30: : | EL30: : | EN30: : | EP30: : | ER30: : | ET30: : | EV30: : | EX30: : | EZ30: : | FB30: : | FD30: : | FF30: 113443.9 | FH30: 115660.6 | FJ30: 111132.4 | FL30: 117687.8 | FN30: 115777.1 | FP30: 119729.7 | FR30: 115294.3 | FT30: 121397.8 | FV30: 120169.9 | FX30: 124909.6 | FZ30: 120532.2 | GB30: 127262.2 | GD30: 127198.1 | GF30: 130769.4 | GH30: 125353.3 | GJ30: 132268.4 | GL30: 132397.8 | GN30: 136262 | GP30: 131437.7 | GR30: 140093.6 | GT30: 139324.8 | GV30: 142718.6 | GX30: 137743.6 | GZ30: 144401.1 | HB30: 143587.8 | HD30: 147001.3 | HF30: 140647.7 | HH30: 146257.8 | HJ30: 143080.8 | HL30: 147528 | HN30: 142021 | HP30: 146128.1 | HR30: 144471.1 | HT30: 146731.8 | HV30: 141161 | HX30: 146737.9 | HZ30: 146556.5 | IB30: 149607.3 | ID30: 144737.8 | IF30: 150383.5 | IH30: 148129.7 | IJ30: 153333.8 | IL30: 148128.8 | IN30: 153925.9 | IP30: 153515 | IR30: 158759.2 | IT30: 152943.5 | IV30: 159123.7 | IX30: 158754.2 | IZ30: 164190.8 | JB30: 159778.3 | JD30: 166465.8 | JF30: 164725.9 | JH30: 170050.8 | JJ30: 164004.3 | JL30: 166332.8 | JN30: 158797.5 | JP30: 162842.5 | JR30: 158223.6 | JT30: 163150.9 | JV30: 158856.8 | JX30: 166284 | JZ30: 161006.1 | KB30: 166435.4 | KD30: 164113.4 | KF30: 170603 | KH30: 164255.3 | KJ30: 167465.9 | KL30: 162675.9 | KN30: 170094.1 | KP30: 162488.2 | KR30: 166242.8 | KT30: 160731.2 | KV30: 170306.7 | KX30: 163662.3 | KZ30: 169247 | LB30: 163396 | LD30: 172990.5 | LF30: 165871.1 | LH30: 172661.3 | LJ30: 166342.2 | LL30: 176327.2 | LN30: 169955.9 | LP30: 175336.9 | LR30: 169865.6 | LT30: 180668.9 | LV30: 173693.6 | LX30: 179180 | LZ30: 175078 | MB30: 185815.2 | MD30: 178391.6 | MF30: 183728.6 | MH30: 179164.1 | MJ30: 190645.2 | ML30: 182038.1 | MN30: 187167.2 | MP30: 183519.5 | MR30: 194996.4 | MT30: 186582.5 | MV30: 191583.3 | MX30: 183062.5 | MZ30: 177634.1 | NB30: 179525.1 | ND30: 185927.3 | NF30: 181050.5 | NH30: 199255.4 | NJ30: 193488.2 | NL30: 200908.1 | NN30: 195179 | NP30: 211448.4 | NR30: 201785.8 | NT30: 210287.9 | NV30: 197680.1 | NX30: 209833.6 | NZ30: 198819.4 | OB30: 207795 | OD30: 197194.9 | OF30: 211997.6 | OH30: 202171.4 | OJ30: 211687.8 | OL30: 201634.6 | ON30: 215735.1 | OP30: 205421.1
A31: Austria | B31: : | D31: : | F31: : | H31: : | J31: : | L31: : | N31: : | P31: : | R31: : | T31: : | V31: : | X31: : | Z31: : | AB31: : | AD31: : | AF31: : | AH31: : | AJ31: : | AL31: : | AN31: : | AP31: : | AR31: : | AT31: : | AV31: : | AX31: : | AZ31: : | BB31: : | BD31: : | BF31: : | BH31: : | BJ31: : | BL31: : | BN31: : | BP31: : | BR31: : | BT31: : | BV31: : | BX31: : | BZ31: : | CB31: : | CD31: : | CF31: : | CH31: : | CJ31: : | CL31: : | CN31: : | CP31: : | CR31: : | CT31: : | CV31: : | CX31: : | CZ31: : | DB31: : | DD31: : | DF31: : | DH31: : | DJ31: : | DL31: : | DN31: : | DP31: : | DR31: : | DT31: : | DV31: : | DX31: : | DZ31: : | EB31: : | ED31: : | EF31: : | EH31: : | EJ31: : | EL31: : | EN31: : | EP31: : | ER31: : | ET31: : | EV31: : | EX31: : | EZ31: : | FB31: : | FD31: : | FF31: 54844.9 | FH31: 58283.2 | FJ31: 58118.4 | FL31: 60510.1 | FN31: 56054.8 | FP31: 59157.1 | FR31: 59306.3 | FT31: 61308.3 | FV31: 57212.8 | FX31: 60334.6 | FZ31: 60345.7 | GB31: 63074.9 | GD31: 59293.6 | GF31: 62683.7 | GH31: 62711.6 | GJ31: 65388 | GL31: 60984.1 | GN31: 64844.2 | GP31: 65023.9 | GR31: 67918.1 | GT31: 63632.3 | GV31: 67002.7 | GX31: 67067.2 | GZ31: 70441.5 | HB31: 65747.3 | HD31: 68159.8 | HF31: 67894.8 | HH31: 70328.3 | HJ31: 66729.4 | HL31: 68993.7 | HN31: 69049.8 | HP31: 71123.4 | HR31: 66558.9 | HT31: 69549.5 | HV31: 70615.7 | HX31: 72788.6 | HZ31: 67992.8 | IB31: 71921.5 | ID31: 72471.9 | IF31: 74772.6 | IH31: 69581.7 | IJ31: 74252.8 | IL31: 73507.8 | IN31: 76883.6 | IP31: 73164 | IR31: 75936.2 | IT31: 75919.2 | IV31: 79650.7 | IX31: 76056.4 | IZ31: 79306.7 | JB31: 79135.8 | JD31: 81969.9 | JF31: 78494 | JH31: 81933.5 | JJ31: 80396.7 | JL31: 81000.2 | JN31: 74489.2 | JP31: 77087.5 | JR31: 77138.8 | JT31: 80221.7 | JV31: 74066.8 | JX31: 78215.6 | JZ31: 79410.4 | KB31: 83026.1 | KD31: 78073.5 | KF31: 81217.2 | KH31: 81329.5 | KJ31: 84345.7 | KL31: 79827.1 | KN31: 81098.8 | KP31: 81343.2 | KR31: 84166.9 | KT31: 78789.9 | KV31: 80813.9 | KX31: 81297.2 | KZ31: 85109.5 | LB31: 79480.2 | LD31: 81233.5 | LF31: 81866.5 | LH31: 85857.2 | LJ31: 80291.3 | LL31: 82035.2 | LN31: 82815.3 | LP31: 86831.7 | LR31: 82025.9 | LT31: 84202.8 | LV31: 83996.7 | LX31: 88655.9 | LZ31: 84805.6 | MB31: 85681.5 | MD31: 85787.4 | MF31: 90732.2 | MH31: 86523.6 | MJ31: 88117.3 | ML31: 87824.4 | MN31: 94010.1 | MP31: 89362 | MR31: 89921.3 | MT31: 89589.9 | MV31: 93974.1 | MX31: 87167.4 | MZ31: 77897.2 | NB31: 86173.4 | ND31: 89291.9 | NF31: 82121.8 | NH31: 88556.9 | NJ31: 90052.2 | NL31: 95113.1 | NN31: 91241.5 | NP31: 94880.1 | NR31: 94049.5 | NT31: 98710.7 | NV31: 94059.4 | NX31: 93360.3 | NZ31: 91575.3 | OB31: 95975 | OD31: 91815.1 | OF31: 92032 | OH31: 90967.2 | OJ31: 96576.6 | OL31: 91746.7 | ON31: 92242.1 | OP31: :
